Workbook

Sheet Summary
C1: Total Value | D1: =SUM(E5:E18) -> 1675929.2
C2: Total ETH | D2: =sum(F5:F12,F14:F18) -> -884.8222
C3: Total BNB | D3: =F13 -> -8.6
A4: Address | B4: Date | C4: Transaction | D4: sent to | E4: Value | F4: Amount | G4: Token
A5: ='0xaadd5f'!B2 -> 0xaadd5f9d0fa1411f612d75336eee5eb87092f1f0 | B5: ='0xaadd5f'!B5 -> 45128.417 | C5: ='0xaadd5f'!C5 -> https://etherscan.io/tx/0x655a2a55bc724718bca78b7645347f448d1ca52b9f051ac3b6b8f2e36651d204 | D5: ='0xaadd5f'!D5 -> depositWithExpiry THORChain 0xD37BbE5744D730a1d98d8DC97c42F0Ca46aD7146 | E5: ='0xaadd5f'!E5 -> 237313.39 | F5: ='0xaadd5f'!F5 -> -125.4472 | G5: ='0xaadd5f'!G5 -> ETH | H5: ='0xaadd5f'!H5 -> 1891.74 | J5: 0x655a2a55bc724718bca78b7645347f448d1ca52b9f051ac3b6b8f2e36651d204
A6: ='0x1c0b5b8'!B5 -> 0x1c0b5b8d36587d0516839df7ebfb49ad8f3c543c | B6: ='0x1c0b5b8'!B8 -> 45129.245 | C6: ='0x1c0b5b8'!C8 -> https://etherscan.io/tx/0xb5e309a09f479a87f71b1258380d8b8e62c84163364b3b06762927c476c4d655 | D6: ='0x1c0b5b8'!D8 -> 0x6a7E9ed15eA2C1C7787E68F2CA2dF68379ed437e | E6: ='0x1c0b5b8'!E8 -> 1530.3 | F6: ='0x1c0b5b8'!F8 -> -0.82 | G6: ='0x1c0b5b8'!G8 -> ETH | H6: ='0x1c0b5b8'!H8 -> 1866.22 | J6: 0xb5e309a09f479a87f71b1258380d8b8e62c84163364b3b06762927c476c4d655
A7: ='0x1c0b5b8'!B5 -> 0x1c0b5b8d36587d0516839df7ebfb49ad8f3c543c | B7: ='0x1c0b5b8'!B9 -> 45128.414 | C7: ='0x1c0b5b8'!C9 -> https://etherscan.io/tx/0x662e469715056d9501da5184ec4a2a466b05b3fa656c73d0fb067598b88013c2 | D7: ='0x1c0b5b8'!D9 -> 0xeEC35fd50B5E7344b3E1A7F4384b3Cb9365e204A | E7: ='0x1c0b5b8'!E9 -> 1178554 | F7: ='0x1c0b5b8'!F9 -> -623 | G7: ='0x1c0b5b8'!G9 -> ETH | H7: ='0x1c0b5b8'!H9 -> 1891.74 | J7: 0x662e469715056d9501da5184ec4a2a466b05b3fa656c73d0fb067598b88013c2
A8: ='0x1c0b5b8'!B5 -> 0x1c0b5b8d36587d0516839df7ebfb49ad8f3c543c | B8: ='0x1c0b5b8'!B10 -> 45128.408 | C8: ='0x1c0b5b8'!C10 -> https://etherscan.io/tx/0x2ed79b067f3afa2e636ae82f8c0c6cbd59d504aa7f25f146a4d22ef2186fc157 | D8: ='0x1c0b5b8'!D10 -> 0xeEC35fd50B5E7344b3E1A7F4384b3Cb9365e204A | E8: ='0x1c0b5b8'!E10 -> 197308.48 | F8: ='0x1c0b5b8'!F10 -> -104.3 | G8: ='0x1c0b5b8'!G10 -> ETH | H8: ='0x1c0b5b8'!H10 -> 1891.74 | J8: 0x2ed79b067f3afa2e636ae82f8c0c6cbd59d504aa7f25f146a4d22ef2186fc157
A9: ='0x055e6b08'!C4 -> 0x055e6b081f175db1170350ba4f23e3a8e0895492 | B9: ='0x055e6b08'!C6 -> 45128.421 | C9: ='0x055e6b08'!D6 -> https://etherscan.io/tx/0x91a3d5976df4c7fb6d000a081855b4fc217d61d6e1b71f5c99205e7dc7c2f63f | D9: ='0x055e6b08'!E6 -> 0x4ec986035b635d09474fc390acdf5c107dda4c70 | E9: ='0x055e6b08'!F6 -> 5372.54 | F9: ='0x055e6b08'!G6 -> -2.84 | G9: ='0x055e6b08'!H6 -> ETH | H9: ='0x055e6b08'!I6 -> 1891.74 | J9: 0x91a3d5976df4c7fb6d000a081855b4fc217d61d6e1b71f5c99205e7dc7c2f63f
A10: ='0xd20a9'!B5 -> 0xd20a9ed00e37fdaef0a064bc32feb10845053f09 | B10: ='0xd20a9'!B8 -> 45128.425 | C10: ='0xd20a9'!C8 -> https://etherscan.io/tx/0xc2235fdf93d6ed97f17ea248d40fbc6c910cb502a63c75f0bb131bbb0fb465a8 | D10: ='0xd20a9'!D8 -> 0xb7917ee3520c4aa56add5d55f6026edeebe99d02 | E10: ='0xd20a9'!E8 -> 12203.61 | F10: ='0xd20a9'!F8 -> -6.451 | G10: ='0xd20a9'!G8 -> ETH | H10: ='0xd20a9'!H8 -> 1891.74 | J10: 0xc2235fdf93d6ed97f17ea248d40fbc6c910cb502a63c75f0bb131bbb0fb465a8
A11: ='0xa30e54c'!B5 -> 0xa30e54cb3593c6afca653621c4d3ee2105f015aa | B11: ='0xa30e54c'!B8 -> 45128.423 | C11: ='0xa30e54c'!C8 -> https://etherscan.io/tx/0x931ebd9671d532e81ef15211ce16e193615765747e4a906d9dabb278f792f2f3 | D11: ='0xa30e54c'!D8 -> 0xbdC4b2D85d9DCC42C3799b4569bd1D7D25D29C03 | E11: ='0xa30e54c'!E8 -> 11445.03 | F11: ='0xa30e54c'!F8 -> -6.05 | G11: ='0xa30e54c'!G8 -> ETH | H11: ='0xa30e54c'!H8 -> 1891.74 | J11: 0x931ebd9671d532e81ef15211ce16e193615765747e4a906d9dabb278f792f2f3
A12: ='0xdFb05'!B5 -> 0xdFb05c98320D126Bcc74F6EB7960E99669dcd49a | B12: ='0xdFb05'!B8 -> 45128.426 | C12: ='0xdFb05'!C8 -> https://etherscan.io/tx/0x0fa037ee4e0a99004dd98ca4827a9aaa9e45e56acd2b74334f09b16ad57050c3 | D12: ='0xdFb05'!D8 -> 0xB7917eE3520C4AA56ADd5d55f6026EdeEBE99d02 | E12: ='0xdFb05'!E8 -> 3541.34 | F12: ='0xdFb05'!F8 -> -1.872 | G12: ='0xdFb05'!G8 -> ETH | H12: ='0xdFb05'!H8 -> 1891.74 | J12: 0x0fa037ee4e0a99004dd98ca4827a9aaa9e45e56acd2b74334f09b16ad57050c3
A13: ='0x9Dc08'!B5 -> 0x9Dc08Da4cBF74F81CFfb54CECbD8fDf6554E1D34 | B13: ='0x9Dc08'!B8 -> 45128.609 | C13: ='0x9Dc08'!C8 -> https://bscscan.com/tx/0x266ef6a62efc7fc3e6e8c9e4c0d31f844208429d9e3b58f5d998f8da58c230d1 | D13: ='0x9Dc08'!D8 -> 0x08178b429CA29853fa33014F635D12bD7f706297 | E13: ='0x9Dc08'!E8 -> 2096.68 | F13: ='0x9Dc08'!F8 -> -8.6 | G13: ='0x9Dc08'!G8 -> BNB | H13: ='0x9Dc08'!H8 -> 243.8 | J13: 0x266ef6a62efc7fc3e6e8c9e4c0d31f844208429d9e3b58f5d998f8da58c230d1
A14: ='0x9Dc08'!B5 -> 0x9Dc08Da4cBF74F81CFfb54CECbD8fDf6554E1D34 | B14: ='0x9Dc08'!B9 -> 45128.426 | C14: ='0x9Dc08'!C9 -> https://etherscan.io/tx/0xa2dc0cff0e555bf26d8044e39e92071e69587e62bfe4128f827b0eb9bdfc8681 | D14: ='0x9Dc08'!D9 -> 0xB7917eE3520C4AA56ADd5d55f6026EdeEBE99d02 | E14: ='0x9Dc08'!E9 -> 2971.92 | F14: ='0x9Dc08'!F9 -> -1.571 | G14: ='0x9Dc08'!G9 -> ETH | H14: ='0x9Dc08'!H9 -> 1891.74 | J14: 0xa2dc0cff0e555bf26d8044e39e92071e69587e62bfe4128f827b0eb9bdfc8681
A15: ='0x265626'!B5 -> 0x2656269bb878ca0c4250a0df4c15a9cfca0c21ac | B15: ='0x265626'!B8 -> 45128.622 | C15: ='0x265626'!C8 -> https://etherscan.io/tx/0x72d855932534ca55ae820f5ed17de8ac729b1f05b093352b5bca19dcf868f26f | D15: ='0x265626'!D8 -> 0x09066E7857D3a9a53c9142f8a7eFFcBc7989F1B5 | E15: ='0x265626'!E8 -> 7358.87 | F15: ='0x265626'!F8 -> -3.89 | G15: ='0x265626'!G8 -> ETH | H15: ='0x265626'!H8 -> 1891.74 | J15: 0x72d855932534ca55ae820f5ed17de8ac729b1f05b093352b5bca19dcf868f26f
A16: ='0x265626'!B5 -> 0x2656269bb878ca0c4250a0df4c15a9cfca0c21ac | B16: ='0x265626'!B9 -> 45128.426 | C16: ='0x265626'!C9 -> https://etherscan.io/tx/0xd5a730adbe95e809d765372997260dd7057e959399e9b41d415816218de3686d | D16: ='0x265626'!D9 -> 0xB7917eE3520C4AA56ADd5d55f6026EdeEBE99d02 | E16: ='0x265626'!E9 -> 1413.13 | F16: ='0x265626'!F9 -> -0.747 | G16: ='0x265626'!G9 -> ETH | H16: ='0x265626'!H9 -> 1891.74 | J16: 0xd5a730adbe95e809d765372997260dd7057e959399e9b41d415816218de3686d
A17: ='0xFA5F6e'!B5 -> 0xFA5F6eD82Ae1EAC484B91cCDE42fe7d64cb68D03 | B17: ='0xFA5F6e'!B8 -> 45128.425 | C17: ='0xFA5F6e'!C8 -> https://etherscan.io/tx/0x3f58b9738767a04a8d4701052cbfa378f7cdf9d8a0cfac34b43b0d62f766a7e8 | D17: ='0xFA5F6e'!D8 -> 0xB7917eE3520C4AA56ADd5d55f6026EdeEBE99d02 | E17: ='0xFA5F6e'!E8 -> 9496.53 | F17: ='0xFA5F6e'!F8 -> -5.02 | G17: ='0xFA5F6e'!G8 -> ETH | H17: ='0xFA5F6e'!H8 -> 1891.74 | J17: 0x3f58b9738767a04a8d4701052cbfa378f7cdf9d8a0cfac34b43b0d62f766a7e8
A18: ='0xf40c0'!B5 -> 0xf40c09C782C74e932b81473ae68B078F31a358f6 | B18: ='0xf40c0'!B8 -> 45128.426 | C18: ='0xf40c0'!C8 -> https://etherscan.io/tx/0x85955c171d41591fb52b85f3e4135704f2afb4305ea9ceee1de1ba503703e7f1 | D18: ='0xf40c0'!D8 -> 0xB7917eE3520C4AA56ADd5d55f6026EdeEBE99d02 | E18: ='0xf40c0'!E8 -> 5323.36 | F18: ='0xf40c0'!F8 -> -2.814 | G18: ='0xf40c0'!G8 -> ETH | H18: ='0xf40c0'!H8 -> 1891.74 | J18: 0x85955c171d41591fb52b85f3e4135704f2afb4305ea9ceee1de1ba503703e7f1
A20: On xx my 10 hot wallets were exploited and the majority of it went to the Thorchain router, however, some money were directly and indirectly (sent to another wallet then deposited) deposited into Fixed Float
A23: All My wallets
A24: {=UNIQUE(A5:A18)} -> 0xaadd5f9d0fa1411f612d75336eee5eb87092f1f0
A25: 0x1c0b5b8d36587d0516839df7ebfb49ad8f3c543c
A26: 0x055e6b081f175db1170350ba4f23e3a8e0895492
A27: 0xd20a9ed00e37fdaef0a064bc32feb10845053f09
A28: 0xa30e54cb3593c6afca653621c4d3ee2105f015aa
A29: 0xdFb05c98320D126Bcc74F6EB7960E99669dcd49a
A30: 0x9Dc08Da4cBF74F81CFfb54CECbD8fDf6554E1D34
A31: 0x2656269bb878ca0c4250a0df4c15a9cfca0c21ac
A32: 0xFA5F6eD82Ae1EAC484B91cCDE42fe7d64cb68D03
A33: 0xf40c09C782C74e932b81473ae68B078F31a358f6
A35: Platforms money was sent to
A36: https://platform.arkhamintelligence.com/visualizer/entity/0xaadd5f9d0fa1411F612d75336EEe5eb87092f1F0,0x1c0b5b8D36587d0516839df7EbFB49AD8F3c543c,0x055e6b081F175dB1170350Ba4f23E3a8E0895492,0xd20A9Ed00E37fdaEF0a064Bc32feB10845053F09,0xa30E54Cb3593c6afCA653621C4D3Ee2105F015aa,0xdFb05c98320D126Bcc74F6EB7960E99669dcd49a,0x9Dc08Da4cBF74F81CFfb54CECbD8fDf6554E1D34,0x2656269BB878cA0c4250A0DF4C15A9CFca0C21AC,0xFA5F6eD82Ae1EAC484B91cCDE42fe7d64cb68D03,0xf40c09C782C74e932b81473ae68B078F31a358f6?fbclid=IwAR3n8Zh-GYgyHRfDSksJm_D-pdT4jCjjlg9gwiFx-Q2ZPZ0Caxc3Qzz9n8M&flow=all&positions=%7B%7D&sortDir=desc&sortKey=time&timeGte=1688774400000&usdGte=0.1
A37: Fixed FLoat
... A39: Deposit to Fixed Float
A40: My Wallet | B40: Time | C40: Amount (ETH) | D40: TX | E40: Fixed Float Wallet
E41: 0x4E5B2e1dc63F6b91cb6Cd759936495434C7e972F
A42: 0xa30E54Cb3593c6afCA653621C4D3Ee2105F015aa | B42: 21 Jul, 2023 19:15:47 UTC | C42: 3.88 | D42: https://etherscan.io/tx/0x931ebd9671d532e81ef15211ce16e193615765747e4a906d9dabb278f792f2f3 | E42: 0xbdC4b2D85d9DCC42C3799b4569bd1D7D25D29C03
A43: 0x055e6b081F175dB1170350Ba4f23E3a8E0895492 | B43: 21 Jul, 2023 14:06 UTC | C43: 2.84 | D43: https://etherscan.io/tx/0x91a3d5976df4c7fb6d000a081855b4fc217d61d6e1b71f5c99205e7dc7c2f63f | E43: 0x4EC986035B635D09474fC390AcDF5c107DDa4c70
A44: 0x2656269BB878cA0c4250A0DF4C15A9CFca0C21AC | B44: 21 Jul, 2023 18:55:47 UTC | C44: 3.89 | D44: https://etherscan.io/tx/0x72d855932534ca55ae820f5ed17de8ac729b1f05b093352b5bca19dcf868f26f | E44: 0x09066E7857D3a9a53c9142f8a7eFFcBc7989F1B5
A45: 0x1c0b5b8D36587d0516839df7EbFB49AD8F3c543c | B45: 22 Jul, 2023 09:52:11 UTC | C45: 0.82 | D45: https://etherscan.io/tx/0xb5e309a09f479a87f71b1258380d8b8e62c84163364b3b06762927c476c4d655 | E45: 0x1c0b5b8D36587d0516839df7EbFB49AD8F3c543c
...

Sheet Fixed Float Deposit

Sheet Sheet5

Sheet 0xaadd5f
A1: Transations | B1: https://debank.com/profile/0xaadd5f9d0fa1411f612d75336eee5eb87092f1f0/history?mode=analysis
A2: Address | B2: 0xaadd5f9d0fa1411f612d75336eee5eb87092f1f0
B4: Date | C4: Transaction | D4: sent to | E4: Value
A5: ETH | B5: 45128.417 | C5: https://etherscan.io/tx/0x655a2a55bc724718bca78b7645347f448d1ca52b9f051ac3b6b8f2e36651d204 | D5: depositWithExpiry THORChain 0xD37BbE5744D730a1d98d8DC97c42F0Ca46aD7146 | E5: 237313.39 | F5: -125.4472 | G5: ETH | H5: 1891.74

Sheet 0x1c0b5b8
A4: Transations | B4: https://debank.com/profile/0x1c0b5b8d36587d0516839df7ebfb49ad8f3c543c/history
A5: Address | B5: 0x1c0b5b8d36587d0516839df7ebfb49ad8f3c543c
B7: Date | C7: Transaction | D7: Sent To | E7: Value
B8: 45129.245 | C8: https://etherscan.io/tx/0xb5e309a09f479a87f71b1258380d8b8e62c84163364b3b06762927c476c4d655 | D8: 0x6a7E9ed15eA2C1C7787E68F2CA2dF68379ed437e | E8: 1530.3 | F8: -0.82 | G8: ETH | H8: 1866.22
B9: 45128.414 | C9: https://etherscan.io/tx/0x662e469715056d9501da5184ec4a2a466b05b3fa656c73d0fb067598b88013c2 | D9: 0xeEC35fd50B5E7344b3E1A7F4384b3Cb9365e204A | E9: 1178554 | F9: -623 | G9: ETH | H9: 1891.74
B10: 45128.408 | C10: https://etherscan.io/tx/0x2ed79b067f3afa2e636ae82f8c0c6cbd59d504aa7f25f146a4d22ef2186fc157 | D10: 0xeEC35fd50B5E7344b3E1A7F4384b3Cb9365e204A | E10: 197308.48 | F10: -104.3 | G10: ETH | H10: 1891.74

Sheet 0x055e6b08
A3: Transations | B3: https://debank.com/profile/0x055e6b081f175db1170350ba4f23e3a8e0895492/history
B4: Address | C4: 0x055e6b081f175db1170350ba4f23e3a8e0895492
C5: Date | D5: Transaction | E5: Sent to | F5: Value | I5: Sent to
C6: 45128.421 | D6: https://etherscan.io/tx/0x91a3d5976df4c7fb6d000a081855b4fc217d61d6e1b71f5c99205e7dc7c2f63f | E6: 0x4ec986035b635d09474fc390acdf5c107dda4c70 | F6: 5372.54 | G6: -2.84 | H6: ETH | I6: 1891.74

Sheet 0xd20a9
A4: Transations | B4: https://debank.com/profile/0xd20a9ed00e37fdaef0a064bc32feb10845053f09/history
A5: Address | B5: 0xd20a9ed00e37fdaef0a064bc32feb10845053f09
B7: Date | C7: Transaction | D7: To | E7: Value
B8: 45128.425 | C8: https://etherscan.io/tx/0xc2235fdf93d6ed97f17ea248d40fbc6c910cb502a63c75f0bb131bbb0fb465a8 | D8: 0xb7917ee3520c4aa56add5d55f6026edeebe99d02 | E8: 12203.61 | F8: -6.451 | G8: ETH | H8: 1891.74

Sheet 0xa30e54c
A4: Transations | B4: https://debank.com/profile/0xa30e54cb3593c6afca653621c4d3ee2105f015aa/history?token=eth_ETH_eth
A5: Address | B5: 0xa30e54cb3593c6afca653621c4d3ee2105f015aa
B7: Date | C7: Transaction | D7: To | E7: Value
B8: 45128.423 | C8: https://etherscan.io/tx/0x931ebd9671d532e81ef15211ce16e193615765747e4a906d9dabb278f792f2f3 | D8: 0xbdC4b2D85d9DCC42C3799b4569bd1D7D25D29C03 | E8: 11445.03 | F8: -6.05 | G8: ETH | H8: 1891.74

Sheet 0xdFb05
A4: Transations | B4: https://debank.com/profile/0xdfb05c98320d126bcc74f6eb7960e99669dcd49a/history?token=eth_ETH_eth
A5: Address | B5: 0xdFb05c98320D126Bcc74F6EB7960E99669dcd49a
B7: Date | C7: Transaction | D7: To | E7: Value
B8: 45128.426 | C8: https://etherscan.io/tx/0x0fa037ee4e0a99004dd98ca4827a9aaa9e45e56acd2b74334f09b16ad57050c3 | D8: 0xB7917eE3520C4AA56ADd5d55f6026EdeEBE99d02 | E8: 3541.34 | F8: -1.872 | G8: ETH | H8: 1891.74

Sheet 0x9Dc08
A4: Transations | B4: https://debank.com/profile/0x9dc08da4cbf74f81cffb54cecbd8fdf6554e1d34/history
A5: Address | B5: 0x9Dc08Da4cBF74F81CFfb54CECbD8fDf6554E1D34
B7: Date | C7: Transaction | D7: To | E7: Value
B8: 45128.609 | C8: https://bscscan.com/tx/0x266ef6a62efc7fc3e6e8c9e4c0d31f844208429d9e3b58f5d998f8da58c230d1 | D8: 0x08178b429CA29853fa33014F635D12bD7f706297 | E8: 2096.68 | F8: -8.6 | G8: BNB | H8: 243.8
B9: 45128.426 | C9: https://etherscan.io/tx/0xa2dc0cff0e555bf26d8044e39e92071e69587e62bfe4128f827b0eb9bdfc8681 | D9: 0xB7917eE3520C4AA56ADd5d55f6026EdeEBE99d02 | E9: 2971.92 | F9: -1.571 | G9: ETH | H9: 1891.74

Sheet 0x265626
A4: Transations | B4: https://debank.com/profile/0x2656269bb878ca0c4250a0df4c15a9cfca0c21ac/history?token=
A5: Address | B5: 0x2656269bb878ca0c4250a0df4c15a9cfca0c21ac
B7: Date | C7: Transaction | D7: To | E7: Value
B8: 45128.622 | C8: https://etherscan.io/tx/0x72d855932534ca55ae820f5ed17de8ac729b1f05b093352b5bca19dcf868f26f | D8: 0x09066E7857D3a9a53c9142f8a7eFFcBc7989F1B5 | E8: 7358.87 | F8: -3.89 | G8: ETH | H8: 1891.74
B9: 45128.426 | C9: https://etherscan.io/tx/0xd5a730adbe95e809d765372997260dd7057e959399e9b41d415816218de3686d | D9: 0xB7917eE3520C4AA56ADd5d55f6026EdeEBE99d02 | E9: 1413.13 | F9: -0.747 | G9: ETH | H9: 1891.74

Sheet 0xFA5F6e
A4: Transations | B4: https://debank.com/profile/0xfa5f6ed82ae1eac484b91ccde42fe7d64cb68d03/history
A5: Address | B5: 0xFA5F6eD82Ae1EAC484B91cCDE42fe7d64cb68D03
B7: Date | C7: Transaction | D7: To | E7: Value
B8: 45128.425 | C8: https://etherscan.io/tx/0x3f58b9738767a04a8d4701052cbfa378f7cdf9d8a0cfac34b43b0d62f766a7e8 | D8: 0xB7917eE3520C4AA56ADd5d55f6026EdeEBE99d02 | E8: 9496.53 | F8: -5.02 | G8: ETH | H8: 1891.74

Sheet 0xf40c0
A4: Transations | B4: https://debank.com/profile/0xf40c09c782c74e932b81473ae68b078f31a358f6/history
A5: Address | B5: 0xf40c09C782C74e932b81473ae68B078F31a358f6
B7: Date | C7: Transaction | D7: To | E7: Value
B8: 45128.426 | C8: https://etherscan.io/tx/0x85955c171d41591fb52b85f3e4135704f2afb4305ea9ceee1de1ba503703e7f1 | D8: 0xB7917eE3520C4AA56ADd5d55f6026EdeEBE99d02 | E8: 5323.36 | F8: -2.814 | G8: ETH | H8: 1891.74
